2025-03-10 14:08:06,597 INFO    MainThread:24296 [wandb_init.py:setup_run_log_directory():647] Logging user logs to C:\Users\Ashutosh Patidar\OneDrive\Documents\GitHub\Assignment_1_Deep_Learning\wandb\run-20250310_140806-zk3l84g6\logs\debug.log
2025-03-10 14:08:06,601 INFO    MainThread:24296 [wandb_init.py:setup_run_log_directory():648] Logging internal logs to C:\Users\Ashutosh Patidar\OneDrive\Documents\GitHub\Assignment_1_Deep_Learning\wandb\run-20250310_140806-zk3l84g6\logs\debug-internal.log
2025-03-10 14:08:06,603 INFO    MainThread:24296 [wandb_init.py:init():761] calling init triggers
2025-03-10 14:08:06,606 INFO    MainThread:24296 [wandb_init.py:init():766] wandb.init called with sweep_config: {}
config: {'Learning_rate': 0.001, 'epochs': 50, 'batch_size': 32, 'layer_size': [784, 128, 64, 10], 'optimizer': 'RMS_Prop', 'beta_1': 0.9, 'beta_2': 0.999, 'loss_function': 'mean_squared', 'weight_decay': 0, 'activation_function': 'ReLu', '_wandb': {}}
2025-03-10 14:08:06,609 INFO    MainThread:24296 [wandb_init.py:init():776] wandb.init() called while a run is active
2025-03-10 14:08:06,612 INFO    MainThread:24296 [wandb_config.py:__setitem__():154] config set beta_1 = 0.9 - <bound method Run._config_callback of <wandb.sdk.wandb_run.Run object at 0x00000274DA9E1FA0>>
2025-03-10 14:08:06,615 INFO    MainThread:24296 [wandb_run.py:_config_callback():1261] config_cb beta_1 0.9 None
2025-03-10 14:08:06,619 INFO    MainThread:24296 [wandb_config.py:__setitem__():154] config set beta_2 = 0.999 - <bound method Run._config_callback of <wandb.sdk.wandb_run.Run object at 0x00000274DA9E1FA0>>
2025-03-10 14:08:06,622 INFO    MainThread:24296 [wandb_run.py:_config_callback():1261] config_cb beta_2 0.999 None
2025-03-10 14:08:06,626 INFO    MainThread:24296 [wandb_config.py:__setitem__():154] config set epochs = 10 - <bound method Run._config_callback of <wandb.sdk.wandb_run.Run object at 0x00000274DA9E1FA0>>
2025-03-10 14:08:06,628 INFO    MainThread:24296 [wandb_run.py:_config_callback():1261] config_cb epochs 10 None
2025-03-10 14:08:06,632 INFO    MainThread:24296 [wandb_config.py:__setitem__():154] config set loss_function = categorical_cross_entropy - <bound method Run._config_callback of <wandb.sdk.wandb_run.Run object at 0x00000274DA9E1FA0>>
2025-03-10 14:08:06,635 INFO    MainThread:24296 [wandb_run.py:_config_callback():1261] config_cb loss_function categorical_cross_entropy None
2025-03-10 14:08:06,638 INFO    MainThread:24296 [wandb_config.py:__setitem__():154] config set weight_decay = 0 - <bound method Run._config_callback of <wandb.sdk.wandb_run.Run object at 0x00000274DA9E1FA0>>
2025-03-10 14:08:06,641 INFO    MainThread:24296 [wandb_run.py:_config_callback():1261] config_cb weight_decay 0 None
2025-03-10 14:08:06,644 INFO    MainThread:24296 [wandb_config.py:__setitem__():154] config set optimizer = RMS_Prop - <bound method Run._config_callback of <wandb.sdk.wandb_run.Run object at 0x00000274DA9E1FA0>>
2025-03-10 14:08:06,647 INFO    MainThread:24296 [wandb_run.py:_config_callback():1261] config_cb optimizer RMS_Prop None
2025-03-10 14:09:23,273 INFO    MainThread:24296 [jupyter.py:save_ipynb():386] not saving jupyter notebook
2025-03-10 14:09:23,336 INFO    MainThread:24296 [wandb_init.py:_pause_backend():564] pausing backend
2025-03-10 14:09:23,490 INFO    MainThread:24296 [wandb_init.py:_resume_backend():569] resuming backend
2025-03-10 14:09:26,312 INFO    MainThread:24296 [jupyter.py:save_ipynb():386] not saving jupyter notebook
2025-03-10 14:09:26,317 INFO    MainThread:24296 [wandb_init.py:_pause_backend():564] pausing backend
2025-03-12 08:45:40,056 WARNING MsgRouterThr:24296 [router.py:message_loop():77] message_loop has been closed
Traceback (most recent call last):
  File "C:\Users\Ashutosh Patidar\AppData\Roaming\Python\Python312\site-packages\wandb\sdk\lib\sock_client.py", line 258, in _read_packet_bytes
ConnectionResetError: [WinError 10054] An existing connection was forcibly closed by the remote host

The above exception was the direct cause of the following exception:

Traceback (most recent call last):
  File "C:\Users\Ashutosh Patidar\AppData\Roaming\Python\Python312\site-packages\wandb\sdk\interface\router_sock.py", line 28, in _read_message
    except SockClientClosedError as e:
               ^^^^^^^^^^^^^^^^^^^^^^^^
  File "C:\Users\Ashutosh Patidar\AppData\Roaming\Python\Python312\site-packages\wandb\sdk\lib\sock_client.py", line 285, in read_server_response
  File "C:\Users\Ashutosh Patidar\AppData\Roaming\Python\Python312\site-packages\wandb\sdk\lib\sock_client.py", line 262, in _read_packet_bytes
wandb.sdk.lib.sock_client.SockClientClosedError

The above exception was the direct cause of the following exception:

Traceback (most recent call last):
  File "C:\Users\Ashutosh Patidar\AppData\Roaming\Python\Python312\site-packages\wandb\sdk\interface\router.py", line 70, in message_loop
    if self._mailbox:
                  ^^^^
  File "C:\Users\Ashutosh Patidar\AppData\Roaming\Python\Python312\site-packages\wandb\sdk\interface\router_sock.py", line 30, in _read_message
wandb.sdk.interface.router.MessageRouterClosedError
2025-03-12 08:45:40,773 INFO    MsgRouterThr:24296 [mailbox.py:close():115] Closing mailbox, abandoning 1 handles.
